Workbook

Sheet Anleitung zum Ausfüllen
A1: Anleitung zum Ausfüllen 1. Nur der linke Abschnitt der Vergleichsberechnung ist auszufüllen, es sei denn es erfolgt für den Mitarbeitenden ein unterjähriger Erfahrungsstufenaufstieg. In dem Fall müssen beide Abschnitte ausgefüllt werden. 2. Nur die blau hinterlegten Zellen können ausgefüllt werden. 3. a) Erfolgt kein unterjähriger Stufenaufstieg, tragen Sie in den linken Abschnitt in die blauen Zeilen 2 bis 8 die geforderten Informationen ein. In dem Dropdown-Menü Zeile 9 wählen Sie die Eingruppierung nach TV-L, in Zeile 11 geben Sie den auf den Tag genauen Tätigkeitszeitraum des Mitarbeitenden in Ihrem Projekt an und in Zeile 12 die wöchentliche Arbeitszeit. Tragen Sie nun in Zeile 27 die Krankenkasse des Mitarbeitenden und in Zeile 28 den Arbeitgeberanteil zum individuellen Beitrag der Krankenkasse in Prozent ein. Falls Sie als Träger*in die Umlagen 1,2 oder 3 (Arbeitsunfähigkeit, Mutterschaft, Insolvenz) zahlen, tragen Sie in den Zeilen 33 - 35 den Prozentsatz ein. Jetzt sehen Sie in der Spalte I die gegliederten Personalkosten, für die in Zeile 9 ausgewählte Eingruppierung nach TV-L bezogen auf eine Vollzeitstelle (39,4 h pro Woche). In der Spalte J sehen Sie die Personalkosten bezogen auf die in Zeile 12 ausgewählte wöchentliche Arbeitszeit. In die blauen Felder in Spalte K können Sie nun das von Ihnen gezahlte mtl. Entgelt bzw. falls zutreffend, Besitzstand, Zulagen, VWL und Jahressonderzahlung eintragen. Bedenken Sie, dass der von Ihnen eingetragene Wert keinesfalls höher als der Wert in Spalte J sein darf (=Besserstellungsverbot). In den Zeilen 37 und 38 sehen Sie nun die zulässigen Personalkosten per anno bzw. für den ausgewählten Tätigkeitsraum nach TV-L. Die Differenz in Zeile 39 zeigt an ob Sie über oder unter den zulässigen Kosten liegen. 3. b) Erfolgt ein unterjähriger Stufenaufstieg, sind neben dem linken Abschnitt auch die blauen Felder im rechten Abschnitt auszufüllen. In diesem Fall wird der linke Abschnitt zum Tätigkeitszeitraum vor dem Stufenaufstieg und der rechte Abschnitt zum Tätigkeitsraum nach dem Stufenaufstieg. Passen Sie die Tätigkeitsräume im rechten und linken Abschnitt dementsprechend an. Verfahren Sie bei den blauen Feldern im rechten Abschnitt wie zuvor im linken (s. 3. a). Das Formular wird Ihnen die gesamten Personalkosten am unteren Ende des linken Abschnitts anzeigen. Hinweis: Ab Zeile 44 der Vergleichsberechnung sind die Textfelder ausschließlich für Bearbeitungszwecke der Bewilligungsstelle vorbehalten. Anleitung zum Ausfüllen - Nachweis für unveränderte und ununterbrochene Tätigkeit aus Vorbeschäftigung 1. Nur die blau hinterlegten Zellen können ausgefüllt werden. 2. Tragen Sie bitte in Spalte B den Arbeitgeber ein. 3. Geben Sie in Spalte C die Tätigkeit stichpunktartig ein. 4. Tragen Sie in Spalte D den Beginn der Tätigkeit ein und in Spalte E das Ende der Tätigkeit. 5. Tragen Sie in Spalte F-I bitte das Arbeitsentgelt lt. Arbeitsvertrag ein.

Sheet Nachweis f. Tätigkeit aus Vorb.
A1: Nachweis für unveränderte und ununterbrochene Tätigkeit aus Vorbeschäftigung:
A4: Lfd. Nr. | B4: Arbeitgeber | C4: Tätigkeit (Info: Angabe nur stichpunktartig) | D4: Beschäftigungszeitraum | F4: Arbeitsentgelt lt. Arbeitsvertrag analog od. in Anlehnung an:
D5: von | E5: bis | F5: BAT 1) | G5: TVöD 1) | H5: TV-L 1) | I5: Sonstiges 2)
A6: 1
A7: 2
A8: 3
A9: 4
A10: 1) | B10: Entgeltgruppe und dazugehörige Stufe gem. TV-L
A11: 2) | B11: Haustarif mit Gewerkschaft/hauseigenes Tarifwerk/einzelvertragliche Regelung/tarifgebunden
B16: ausgestellt am: | D16: Name Ersteller*in | H16: Unterschrift Ersteller*in

Sheet Vergleichsberechnung
A1: Vergleichsberechnung nach TV-L | I1: 2027 | M1: Stufenaufstieg nach TV-L (nur zusätzlich auszufüllen bei unterjährigem Erfahrungsstufenaufstieg!)
A2: Träger | M2: Sprung in Erfahrungsstufe: | P2: Bitte auswählen: | T2: =_xlfn.CONCAT("bis ",TEXT(DATE(I1,Werte!$F$2-1,2),"MMMM")) -> bis Februar | U2: =_xlfn.CONCAT("ab ",TEXT(DATE(I1,Werte!$F$2,2),"MMMM")) -> ab März
A3: Dokument zum Antrag vom | M3: Monate im Projekt (inkl. 2 Dezimalstellen) | P3: =IF(AND(P4<>"",U4<>""), N("monatsanteil startdatum:")+DATEDIF(P4,EOMONTH(P4,0)+1,"D")/DAY(EOMONTH(P4,0)) +N("zwischenmonate bzw korrektur:")+DATEDIF(P4,U4,"M")-IF(OR(MONTH(P4)=MONTH(U4),DAY(P4)<=DAY(U4)),1,0) +N("monatsanteil enddatum:")+DATEDIF(EOMONTH(U4,-1),U4,"D")/DAY(EOMONTH(U4,0)), 0) -> 0 | T3: =IF(AND(P4<>"",U4<>"",MONTH(P4)<Werte!$F$2), +N("monatsanteil startdatum:")+DATEDIF(P4,EOMONTH(P4,0)+1,"D")/DAY(EOMONTH(P4,0)) +N("monatsanteil enddatum, falls vor W2:")+IF(MONTH(U4)<Werte!$F$2,DATEDIF(EOMONTH(U4,-1),U4,"D")/DAY(EOMONTH(U4,0))) +N("zwischenmonate bzw korrektur:")+MIN(MONTH(U4),Werte!$F$2)-MONTH(P4)-1,0) -> 0 | U3: =N("wenn enddatum>=wechseldatum")+IF(MONTH(U4)>=Werte!$F$2, +N("monatsanteil startdatum, wenn >= W2:")+IF(MONTH(P4)>=Werte!$F$2,DATEDIF(P4,EOMONTH(P4,0)+1,"D")/DAY(EOMONTH(P4,0)),0) +N("monatsanteil enddatum")+DATEDIF(EOMONTH(U4,-1),U4,"D")/DAY(EOMONTH(U4,0)) +N("zwischenmonate bzw korrektur:")+MONTH(U4)-MAX(MONTH(P4),Werte!$F$2-1)-1 ) -> 0
A4: Projektnummer | M4: Tätigkeitszeitraum im Projekt von: | S4: bis:
A5: Name / Vorname | M5: wöchentliche AZ lt. AV: | S5: Std. | T5: Vollzeitstelle entspricht 39,4 Stunden
A6: Qualifikation / Berufsabschluss | T6: TV-L lt. Tabellenwert bezogen auf eine ganze Stelle (39,4 Std.) | U6: TV-L rechnet automatisch auf die angegebene wöchentliche Arbeitszeit um | V6: lt. Arbeitsvertrag
A7: Tätigkeit beim Träger | J7: seit:
A8: abweichende Projekttätigkeit
A9: Eingruppierung der Stelle in den TV-L: | E9: Bitte auswählen: | I9: =_xlfn.CONCAT("bis ",TEXT(DATE(I1,Werte!$F$2-1,2),"MMMM")) -> bis Februar | J9: =_xlfn.CONCAT("ab ",TEXT(DATE(I1,Werte!$F$2,2),"MMMM")) -> ab März
A10: Monate im Projekt (inkl. 2 Dezimalstellen) | E10: =N("monatsanteil startdatum:")+DATEDIF(E11,EOMONTH(E11,0)+1,"D")/DAY(EOMONTH(E11,0)) +N("zwischenmonate bzw korrektur:")+DATEDIF(E11,J11,"M")-IF(OR(MONTH(E11)=MONTH(J11),DAY(E11)<=DAY(J11)),1,0) +N("monatsanteil enddatum:")+DATEDIF(EOMONTH(J11,-1),J11,"D")/DAY(EOMONTH(J11,0)) -> 12 | I10: =N("wenn startdatum<wechseldatum")+IF(MONTH(E11)<Werte!$F$2, +N("monatsanteil startdatum:")+DATEDIF(E11,EOMONTH(E11,0)+1,"D")/DAY(EOMONTH(E11,0)) +N("monatsanteil enddatum, falls vor W2:")+IF(MONTH(J11)<Werte!$F$2,DATEDIF(EOMONTH(J11,-1),J11,"D")/DAY(EOMONTH(J11,0))) +N("zwischenmonate bzw korrektur:")+MIN(MONTH(J11),Werte!$F$2)-MONTH(E11)-1) -> 2 | J10: =N("wenn startdatum<wechseldatum")+IF(MONTH(J11)>=Werte!$F$2, +N("monatsanteil startdatum, wenn >= W2:")+IF(MONTH(E11)>=Werte!$F$2,DATEDIF(E11,EOMONTH(E11,0)+1,"D")/DAY(EOMONTH(E11,0)),0) +N("monatsanteil enddatum")+DATEDIF(EOMONTH(J11,-1),J11,"D")/DAY(EOMONTH(J11,0)) +N("zwischenmonate bzw korrektur:")+MONTH(J11)-MAX(MONTH(E11),Werte!$F$2-1)-1) -> 10 | M10: mtl. Tabellenentgelt Januar bis Februar | T10: =INDEX(Werte!C3:C210,MATCH(P2,Werte!$B3:$B210,0)) -> 0 | U10: =ROUND(T10/39.4*$P$5,2) -> 0
A11: Tätigkeitszeitraum im Projekt von: | E11: 46388 | H11: bis: | J11: 46752 | M11: mtl. Tabellenentgelt ab März | T11: =INDEX(Werte!E3:E210,MATCH(P2,Werte!$B3:$B210,0)) -> 0 | U11: =ROUND(T11/39.4*$P$5,2) -> 0
A12: wöchentliche AZ lt. AV: | H12: Std. | I12: Vollzeitstelle entspricht 39,4 Stunden | M12: =A19 -> Zulage SuE (aus der S-Tabelle) | T12: =INDEX(Werte!F3:F210,MATCH(P2,Werte!$B3:$B210,0)) -> 0 | U12: =ROUND(T12/39.4*$P$5,2) -> 0
I13: TV-L lt. Tabellenwert bezogen auf eine ganze Stelle (39,4 Std.) | J13: TV-L rechnet automatisch auf die angegebene wöchentliche Arbeitszeit um | K13: lt. Arbeitsvertrag | M13: =A20 -> Besitzstand, Zulagen (Bitte in einer Anlage erläutern) | U13: =ROUND(T13/39.4*$P$5,2) -> 0
M14: =A21 -> ggf. VWL (§ 23 TV-L) *1 | U14: =IF(P5<39.4,ROUND(T14/39.4*$P$5,2),T14) -> 0
M15: =A22 -> Ø mtl. AN-Brutto ges. (ohne Berücksichtigung der VWL-Zulage) | T15: =ROUND(IF($P3>0,SUM((T10*$T3+T11*$U3)/$P3,T12+T13),0),2) -> 0 | U15: =ROUND(IF($P3>0,SUM((U10*$T3+U11*$U3)/$P3,U12+U13),0),2) -> 0 | V15: =ROUND(IF($P3>0,SUM((V10*$T3+V11*$U3)/$P3,V12+V13),0),2) -> 0
M16: =A23 -> Arbeitnehmerbruttogehalt ohne Jahressonderzahlung | T16: =ROUND(T15*$P3,2) -> 0 | U16: =ROUND(U15*$P3,2) -> 0 | V16: =ROUND(V15*$P3,2) -> 0
A17: mtl. Tabellenentgelt Januar bis Februar | I17: =INDEX(Werte!C3:C210,MATCH(E9,Werte!$B3:$B210,0)) -> 0 | J17: =ROUND(I17/39.4*$E$12,2) -> 0 | M17: Berechungsgrundlage Jahressonderzahlung | R17: =INDEX(Werte!D3:D210,MATCH(Vergleichsberechnung!P2,Werte!$B3:$B210,0)) -> 0
A18: mtl. Tabellenentgelt ab März | I18: =INDEX(Werte!E3:E210,MATCH(E9,Werte!$B3:$B210,0)) -> 0 | J18: =ROUND(I18/39.4*$E$12,2) -> 0 | M18: AN-Brutto Monat Juli | T18: =IF($U$4>=DATEVALUE("01.12."&($I$1)),IF($P$4>=DATEVALUE("01.08."&($I$1)), IF(Werte!$F$2>7,I$17,I$18)+I$19+I$21, IF(Werte!$F$2>7,T$10,T$11)+T$12+T$14),0) -> 0 | U18: =IF($U$4>=DATEVALUE("01.12."&($I$1)),IF($P$4>=DATEVALUE("01.08."&($I$1)), IF(Werte!$F$2>7,J$17,J$18)+J$19+J$21, IF(Werte!$F$2>7,U$10,U$11)+U$12+U$14),0) -> 0 | V18: =IF($U$4>=DATEVALUE("01.12."&($I$1)),IF($P$4>=DATEVALUE("01.08."&($I$1)), IF(Werte!$F$2>7,K$17,K$18)+K$19+K$21, IF(Werte!$F$2>7,V$10,V$11)+V$12+V$14),0) -> 0
A19: Zulage SuE (aus der S-Tabelle) | I19: =INDEX(Werte!F3:F210,MATCH(E9,Werte!$B3:$B210,0)) -> 0 | J19: =ROUND(I19/39.4*$E$12,2) -> 0 | M19: AN-Brutto Monat August | T19: =IF($U$4>=DATEVALUE("01.12."&($I$1)),IF($P$4>=DATEVALUE("01.09."&($I$1)), IF(Werte!$F$2>8,I$17,I$18)+I$19+I$21, IF(Werte!$F$2>8,T$10,T$11)+T$12+T$14),0) -> 0 | U19: =IF($U$4>=DATEVALUE("01.12."&($I$1)),IF($P$4>=DATEVALUE("01.09."&($I$1)), IF(Werte!$F$2>8,J$17,J$18)+J$19+J$21, IF(Werte!$F$2>8,U$10,U$11)+U$12+U$14),0) -> 0 | V19: =IF($U$4>=DATEVALUE("01.12."&($I$1)),IF($P$4>=DATEVALUE("01.09."&($I$1)), IF(Werte!$F$2>8,K$17,K$18)+K$19+K$21, IF(Werte!$F$2>8,V$10,V$11)+V$12+V$14),0) -> 0
A20: Besitzstand, Zulagen (Bitte in einer Anlage erläutern) | J20: =ROUND(I20/39.4*$E$12,2) -> 0 | M20: AN-Brutto Monat September | T20: =IF($U$4>=DATEVALUE("01.12."&($I$1)),IF($P$4>=DATEVALUE("01.10."&($I$1)), IF(Werte!$F$2>9,I$17,I$18)+I$19+I$21, IF(Werte!$F$2>9,T$10,T$11)+T$12+T$14),0) -> 0 | U20: =IF($U$4>=DATEVALUE("01.12."&($I$1)),IF($P$4>=DATEVALUE("01.10."&($I$1)), IF(Werte!$F$2>9,J$17,J$18)+J$19+J$21, IF(Werte!$F$2>9,U$10,U$11)+U$12+U$14),0) -> 0 | V20: =IF($U$4>=DATEVALUE("01.12."&($I$1)),IF($P$4>=DATEVALUE("01.10."&($I$1)), IF(Werte!$F$2>9,K$17,K$18)+K$19+K$21, IF(Werte!$F$2>9,V$10,V$11)+V$12+V$14),0) -> 0
A21: ggf. VWL (§ 23 TV-L) *1 | J21: =IF(E12<39.4,ROUND(I21/39.4*$E$12,2),I21) -> 0 | M21: Jahressonderzahlung (auf Basis Ø AN-Brutto Jul/Aug/Sept) | T21: =IF($U4>=DATEVALUE("01.12."&($I$1)),ROUND(SUM(T18:T20)/3*$R17*(DATEDIF($E11,$U4,"m")+1+IF(DAY($E11)>DAY($U4),1))/12,2),0) -> 0 | U21: =IF($U4>=DATEVALUE("01.12."&($I$1)),ROUND(SUM(U18:U20)/3*$R17*(DATEDIF($E11,$U4,"m")+1+IF(DAY($E11)>DAY($U4),1))/12,2),0) -> 0
A22: Ø mtl. AN-Brutto ges. (ohne Berücksichtigung der VWL-Zulage) | I22: =ROUND(SUM((I17*$I10+(IF(J10>0,I18*$J10,0)))/$E10,I19+I20),2) -> 0 | J22: =ROUND(SUM((J17*$I10+J18*$J10)/$E10,J19+J20),2) -> 0 | K22: =ROUND(SUM((K17*$I10+K18*$J10)/$E10,K19+K20),2) -> 0 | M22: =A25 -> Arbeitnehmerbruttogehalt inkl. Jahressonderzahlung | T22: =T16+T21 -> 0 | U22: =U16+U21 -> 0 | V22: =V16+V21 -> 0
A23: Arbeitnehmerbruttogehalt ohne Jahressonderzahlung | I23: =ROUND(I22*$E10,2) -> 0 | J23: =ROUND(J22*$E10,2) -> 0 | K23: =ROUND(K22*$E10,2) -> 0 | M23: =A26 -> AG-Anteil zur Krankenversicherung in Prozent | R23: =G26 -> 0.073 | T23: =ROUND(T$22*$R23,2) -> 0 | U23: =ROUND(U$22*$R23,2) -> 0 | V23: =ROUND(V$22*$R23,2) -> 0
A24: Jahressonderzahlung nach Beschäftigungszeitraum | G24: =INDEX(Werte!D3:D210,MATCH(Vergleichsberechnung!E9,Werte!$B3:$B210,0)) -> 0 | I24: =IF(AND($J11>=DATEVALUE("01.12."&(I1)),$E11<=DATEVALUE("01.12."&(I1))), ROUND(( IF(Werte!$F$2>9,I17, IF(Werte!$F$2<7,I18, IF(Werte!$F$2=8,(I17+2*I18)/3,(2*I17+I18)/3))) +I19)*$G24*(DATEDIF(E11,J11,"m")+1+IF(DAY(E11)>DAY(J11),1))/12,2),0) -> 0 | J24: =ROUND(I24/39.4*$E$12,2) -> 0 | M24: =A27 -> Bezeichnung Krankenkasse | N24: =IF(ISBLANK(C27),"",C27) -> Techniker Krankenkasse
A25: Arbeitnehmerbruttogehalt inkl. Jahressonderzahlung | I25: =SUM(I23:I24) -> 0 | J25: =SUM(J23:J24) -> 0 | K25: =SUM(K23:K24) -> 0 | M25: =A28 -> AG-Anteil zur KK individueller Beitragssatz in Prozent | R25: =G28 -> 0 | T25: =ROUND(T$22*$R25,2) -> 0 | U25: =ROUND(U$22*$R25,2) -> 0 | V25: =ROUND(V$22*$R25,2) -> 0
A26: AG-Anteil zur Krankenversicherung in Prozent | G26: 0.073 | I26: =ROUND(I25*$G26,2) -> 0 | J26: =ROUND(J25*$G26,2) -> 0 | K26: =ROUND(K25*$G26,2) -> 0 | M26: =A29 -> AG-Anteil zur Rentenversicherung in Prozent | R26: =G29 -> 0.093 | T26: =ROUND(T$22*$R26,2) -> 0 | U26: =ROUND(U$22*$R26,2) -> 0 | V26: =ROUND(V$22*$R26,2) -> 0
A27: Bezeichnung Krankenkasse | C27: Techniker Krankenkasse | M27: =A30 -> AG-Anteil zur Arbeitslosenversicherung in Prozent | R27: =G30 -> 0 | T27: =ROUND(T$22*$R27,2) -> 0 | U27: =ROUND(U$22*$R27,2) -> 0 | V27: =ROUND(V$22*$R27,2) -> 0
A28: AG-Anteil zur KK individueller Beitragssatz in Prozent | I28: =ROUND(I$25*$G28,2) -> 0 | J28: =ROUND(J$25*$G28,2) -> 0 | K28: =ROUND(K$25*$G28,2) -> 0 | M28: =A31 -> AG-Anteil zur Pflegeversicherung in Prozent | R28: =G31 -> 0.018 | T28: =ROUND(T$22*$R28,2) -> 0 | U28: =ROUND(U$22*$R28,2) -> 0 | V28: =ROUND(V$22*$R28,2) -> 0
A29: AG-Anteil zur Rentenversicherung in Prozent | G29: 0.093 | I29: =ROUND(I$25*$G29,2) -> 0 | J29: =ROUND(J$25*$G29,2) -> 0 | K29: =ROUND(K$25*$G29,2) -> 0 | M29: =A32 -> Förderfähige AG-Vorsorgezahlungen (optional) | R29: =G32 -> 0 | T29: =ROUND(T$22*$R29,2) -> 0 | U29: =ROUND(U$22*$R29,2) -> 0
A30: AG-Anteil zur Arbeitslosenversicherung in Prozent | I30: =ROUND(I$25*$G30,2) -> 0 | J30: =ROUND(J$25*$G30,2) -> 0 | K30: =ROUND(K$25*$G30,2) -> 0 | M30: =A33 -> Umlage 1 (Arbeitsunfähigkeit) | R30: =G33 -> 0.021 | T30: =ROUND($R30*T$16,2) -> 0 | U30: =ROUND($R30*U$16,2) -> 0 | V30: =ROUND($R30*V$16,2) -> 0
A31: AG-Anteil zur Pflegeversicherung in Prozent | G31: 0.018 | I31: =ROUND(I$25*$G31,2) -> 0 | J31: =ROUND(J$25*$G31,2) -> 0 | K31: =ROUND(K$25*$G31,2) -> 0 | M31: =A34 -> Umlage 2 (Mutterschaft) | R31: =G34 -> 0.0044 | T31: =ROUND($R31*T$16,2) -> 0 | U31: =ROUND($R31*U$16,2) -> 0 | V31: =ROUND($R31*V$16,2) -> 0
A32: Förderfähige AG-Vorsorgezahlungen (optional) | I32: =ROUND(I$25*$G32,2) -> 0 | J32: =ROUND(J$25*$G32,2) -> 0 | K32: 0 | M32: =A35 -> Umlage 3 (Insolvenz) | R32: =G35 -> 0.0015 | T32: =ROUND($R32*T$22,2) -> 0 | U32: =ROUND($R32*U$22,2) -> 0 | V32: =ROUND($R32*V$22,2) -> 0
A33: Umlage 1 (Arbeitsunfähigkeit) | G33: 0.021 | I33: =ROUND(I$23*$G33,2) -> 0 | J33: =ROUND(J$23*$G33,2) -> 0 | K33: =ROUND(K$23*$G33,2) -> 0 | M33: =A36 -> Arbeitgeber-SV gesamt | T33: =SUM(T23:T32) -> 0 | U33: =SUM(U23:U32) -> 0 | V33: =SUM(V23:V32) -> 0
A34: Umlage 2 (Mutterschaft) | G34: 0.0044 | I34: =ROUND(I$23*$G34,2) -> 0 | J34: =ROUND(J$23*$G34,2) -> 0 | K34: =ROUND(K$23*$G34,2) -> 0 | M34: Personalkosten nach TV-L / Tätigkeitszeitraum | T34: =SUM(T33+T22+T14*P3) -> 0 | U34: =SUM(U33+U22+U14*P3) -> 0 | V34: =SUM(V33+V22+V14*P3) -> 0
A35: Umlage 3 (Insolvenz) | G35: 0.0015 | I35: =ROUND(I$25*$G35,2) -> 0 | J35: =ROUND(J$25*$G35,2) -> 0 | K35: =ROUND(K$25*$G35,2) -> 0 | M35: Personalkosten Gesamt / Tätigkeitszeitraum (inkl. vorherige Stufe) | T35: =IF($P3>0,SUM(I37,T34),0) -> 0 | U35: =IF($P3>0,SUM(J37,U34),0) -> 0 | V35: =IF($P3>0,SUM(K37,V34),0) -> 0
A36: Arbeitgeber-SV gesamt | I36: =SUM(I26:I35) -> 0 | J36: =SUM(J26:J35) -> 0 | K36: =SUM(K26:K35) -> 0 | M36: Ø monatliches Arbeitgeber-Brutto gesamt | U36: =U35/(P3+E10) -> 0 | V36: =V35/(P3+E10) -> 0
A37: Personalkosten nach TV-L / Tätigkeitszeitraum | I37: =I25+I36+I21*E10 -> 0 | J37: =J25+J36+J21*E10 -> 0 | K37: =K25+K36+K21*E10 -> 0 | R37: Differenz: | U37: =V35-U35 -> 0
A38: Ø monatliches Arbeitgeber-Brutto gesamt | J38: =J37/E10 -> 0 | K38: =K37/E10 -> 0 | M38: Bemerkungen (430 Zeichen)
G39: Differenz: | J39: =K37-J37 -> 0
A40: *ohne soz.-versicherungsfreie (Einmal)zahlungen
...

Sheet Werte
E2: ab März 2027 | F2: 3
B3: Bitte auswählen:
B4: E15Ü/1 | C4: 6857.14 | D4: 0.3253 | E4: 6994.28
B5: E15Ü/2 | C5: 7587.33 | D5: 0.3253 | E5: 7739.08
B6: E15Ü/3 | C6: 8280.33 | D6: 0.3253 | E6: 8445.94
B7: E15Ü/4 | C7: 8734.83 | D7: 0.3253 | E7: 8909.53
B8: E15Ü/5 | C8: 8846.64 | D8: 0.3253 | E8: 9023.57
B9: E15/1 | C9: 5658.38 | D9: 0.3253 | E9: 5771.55
B10: E15/2 | C10: 6067.3 | D10: 0.3253 | E10: 6188.65
B11: E15/3 | C11: 6283.38 | D11: 0.3253 | E11: 6409.05
B12: E15/4 | C12: 7050.89 | D12: 0.3253 | E12: 7191.91
B13: E15/5 | C13: 7632.07 | D13: 0.3253 | E13: 7784.71
B14: E15/6 | C14: 7854.52 | D14: 0.3253 | E14: 8011.61
B15: E14/1 | C15: 5143.59 | D15: 0.3253 | E15: 5246.46
... B132: S16/6 | C132: 5993.21 | D132: 0.7435 | E132: 6113.07
B133: S15/1 | C133: 4040.87 | D133: 0.7435 | E133: 4121.69 | F133: 180
B134: S15/2 | C134: 4385.36 | D134: 0.7435 | E134: 4473.07 | F134: 180
B135: S15/3 | C135: 4683.16 | D135: 0.7435 | E135: 4776.82 | F135: 180
B136: S15/4 | C136: 5025.55 | D136: 0.7435 | E136: 5126.06 | F136: 180
B137: S15/5 | C137: 5576.37 | D137: 0.7435 | E137: 5687.9 | F137: 180
B138: S15/6 | C138: 5814.54 | D138: 0.7435 | E138: 5930.83 | F138: 180
B139: S14/1 | C139: 4020.78 | D139: 0.7435 | E139: 4101.2 | F139: 180
B140: S14/2 | C140: 4342.61 | D140: 0.7435 | E140: 4429.46 | F140: 180
B141: S14/3 | C141: 4673.51 | D141: 0.7435 | E141: 4766.98 | F141: 180
B142: S14/4 | C142: 5010.12 | D142: 0.7435 | E142: 5110.32 | F142: 180
B143: S14/5 | C143: 5382.33 | D143: 0.7435 | E143: 5489.98 | F143: 180
B144: S14/6 | C144: 5642.84 | D144: 0.7435 | E144: 5755.7 | F144: 180
... B180: S8b/6 | C180: 5181.91 | D180: 0.8814 | E180: 5285.55 | F180: 130
B181: S8a/1 | C181: 3444.29 | D181: 0.8814 | E181: 3513.18
B182: S8a/2 | C182: 3717.03 | D182: 0.8814 | E182: 3791.37
B183: S8a/3 | C183: 3963.34 | D183: 0.8814 | E183: 4042.61
B184: S8a/4 | C184: 4196.7 | D184: 0.8814 | E184: 4280.63
B185: S8a/5 | C185: 4423.54 | D185: 0.8814 | E185: 4512.01
B186: S8a/6 | C186: 4660.13 | D186: 0.8814 | E186: 4753.33
B187: S7/1 | C187: 3369.05 | D187: 0.8814 | E187: 3436.43
B188: S7/2 | C188: 3625.89 | D188: 0.8814 | E188: 3698.41
B189: S7/3 | C189: 3855.89 | D189: 0.8814 | E189: 3933.01
B190: S7/4 | C190: 4087.12 | D190: 0.8814 | E190: 4168.86
B191: S7/5 | C191: 4260.59 | D191: 0.8814 | E191: 4345.8
B192: S7/6 | C192: 4519.37 | D192: 0.8814 | E192: 4609.76
...
